<?xml version="1.0" ?>
<sdf version="1.5">
  <model name="basic_mobile_bot">
    <static>false</static>

    <!-- ****************** ROBOT BASE FOOTPRINT *************************** -->
    <pose>0.0 0.0 0.0 0.0 0.0 0.0</pose>
    <link name="base_footprint"/>

    <!-- ********************** ROBOT BASE ********************************* -->
    <link name="base_link">
      <collision name="base_collision">
        <pose>0 0 0.1 0 0 0</pose>
        <geometry>
          <box>
            <size>0.70 0.39 0.20</size>
          </box>
        </geometry>
      </collision>
      <visual name="base_visual">
        <pose>0 0 -0.05 1.5707963267949 0 3.141592654</pose>
        <geometry>
          <mesh>
            <uri>model://basic_mobile_bot_description/meshes/robot_base.stl</uri>
            <scale>1.0 1.0 1.0</scale>
          </mesh>
        </geometry>
        <material>
          <ambient>1.0 0.0 0.0 1.0</ambient>
          <diffuse>1.0 0.0 0.0 1.0</diffuse>
          <specular>0.0 0.0 0.0 1.0</specular>
          <emissive>0.0 0.0 0.0 1.0</emissive>
        </material>
      </visual>
    </link>

    <!-- *********************** IMU SENSOR SETUP ************************** -->
    <link name="imu_link">
      <gravity>true</gravity>
      <sensor name="bmb_imu" type="imu">
        <always_on>true</always_on>
        <update_rate>100</update_rate>
        <visualize>true</visualize>
        <imu>
          <orientation>
            <x>
              <noise type="gaussian">
                <mean>0.0</mean>
                <stddev>2e-3</stddev>
              </noise>
            </x>
            <y>
              <noise type="gaussian">
                <mean>0.0</mean>
                <stddev>2e-3</stddev>
              </noise>
            </y>
            <z>
              <noise type="gaussian">
                <mean>0.0</mean>
                <stddev>2e-3</stddev>
              </noise>
            </z>
          </orientation>
          <angular_velocity>
            <x>
              <noise type="gaussian">
                <mean>0.0</mean>
                <stddev>2e-4</stddev>
              </noise>
            </x>
            <y>
              <noise type="gaussian">
                <mean>0.0</mean>
                <stddev>2e-4</stddev>
              </noise>
            </y>
            <z>
              <noise type="gaussian">
                <mean>0.0</mean>
                <stddev>2e-4</stddev>
              </noise>
            </z>
          </angular_velocity>
          <linear_acceleration>
            <x>
              <noise type="gaussian">
                <mean>0.0</mean>
                <stddev>1.7e-2</stddev>
              </noise>
            </x>
            <y>
              <noise type="gaussian">
                <mean>0.0</mean>
                <stddev>1.7e-2</stddev>
              </noise>
            </y>
            <z>
              <noise type="gaussian">
                <mean>0.0</mean>
                <stddev>1.7e-2</stddev>
              </noise>
            </z>
          </linear_acceleration>
        </imu>
        <plugin name="basic_mobile_bot_imu" filename="libgazebo_ros_imu_sensor.so">
          <initial_orientation_as_reference>false</initial_orientation_as_reference>
          <frame_name>imu_link</frame_name>
          <ros>
            <namespace>/imu</namespace>
            <remapping>~/out:=data</remapping>
          </ros>
        </plugin>
      </sensor>
    </link>

    <!-- *********************** GPS SETUP ********************************* -->
    <link name="gps_link">
      <sensor name="bmb_gps" type="gps">
        <always_on>true</always_on>
        <update_rate>10.0</update_rate>
        <gps>
          <position_sensing>
            <horizontal>
              <noise type="gaussian">
                <mean>0.0</mean>
                <stddev>1e-2</stddev>
              </noise>
            </horizontal>
            <vertical>
              <noise type="gaussian">
                <mean>0.0</mean>
                <stddev>1</stddev>
              </noise>
            </vertical>
          </position_sensing>
        </gps>
        <plugin name="basic_mobile_bot_gps" filename="libgazebo_ros_gps_sensor.so">
          <ros>
            <remapping>~/out:=gps/fix</remapping>
          </ros>
        </plugin>
      </sensor>
    </link>

    <!-- *********************** DRIVE WHEELS ****************************** -->
    <link name="rear_left_wheel_link">
      <pose>-0.221 0.23 -0.05 0 1.570796 1.570796</pose>
      <collision name="rear_left_wheel_collision">
        <geometry>
          <cylinder>
            <radius>0.14</radius>
            <length>0.06</length>
          </cylinder>
        </geometry>
      </collision>
      <visual name="rear_left_wheel_visual">
        <geometry>
          <cylinder>
            <radius>0.14</radius>
            <length>0.06</length>
          </cylinder>
        </geometry>
      </visual>
    </link>

    <link name="rear_right_wheel_link">
       <pose>-0.221 -0.23 -0.05 0 1.570796 1.570796</pose>
      <collision name="rear_right_wheel_collision">
        <geometry>
          <cylinder>
            <radius>0.14</radius>
            <length>0.06</length>
          </cylinder>
        </geometry>
      </collision>
      <visual name="rear_right_wheel_visual">
        <geometry>
          <cylinder>
            <radius>0.14</radius>
            <length>0.06</length>
          </cylinder>
        </geometry>
      </visual>
    </link>

    <!-- ************************* STEERING LINK ******************************-->
    <link name="steering_link">
      <pose>0 0 0 0 0 0</pose>
    </link>

    <!-- *********************** STEERING WHEEL ****************************** -->
    <link name="front_steering_wheel_link">
      <pose>0.217 0 -0.1 0 1.570796 1.570796</pose>
      <collision name="front_steering_wheel_collision">
        <geometry>
          <cylinder>
            <radius>0.09</radius>
            <length>0.06</length>
          </cylinder>
        </geometry>
      </collision>
      <visual name="front_steering_wheel_visual">
        <geometry>
          <cylinder>
            <radius>0.09</radius>
            <length>0.06</length>
          </cylinder>
        </geometry>
      </visual>
    </link>

    <!-- ************************ JOINTS *********************************** -->
    <joint name="base_joint" type="fixed">
      <parent>base_footprint</parent>
      <child>base_link</child>
      <pose>0 0 0 0 0 0</pose>
    </joint>

    <joint name="rear_left_wheel_joint" type="revolute">
      <parent>base_link</parent>
      <child>rear_left_wheel_link</child>
      <pose>0 0 0 0 0 0</pose>
      <axis>
        <xyz>0 0 1</xyz>
      </axis>
    </joint>

    <joint name="rear_right_wheel_joint" type="revolute">
      <parent>base_link</parent>
      <child>rear_right_wheel_link</child>
      <pose>0 0 0 0 0 0</pose>
      <axis>
        <xyz>0 0 1</xyz>
      </axis>
    </joint>
    
    <joint name="steering_joint" type="fixed">
      <parent>base_link</parent>
      <child>steering_link</child>
      <pose>0 0 0 0 0 0</pose>

    </joint>

    <joint name="front_steering_wheel_joint" type="revolute">
      <parent>steering_link</parent>
      <child>front_steering_wheel_link</child>
      <pose>0 0 0 0 0 0</pose>
      <axis>
        <xyz>0 0 1</xyz>
      </axis>
    </joint>

    <joint name="imu_joint" type="fixed">
      <parent>base_link</parent>
      <child>imu_link</child>
      <pose>0 0 0 0 0 0</pose>
    </joint>

    <joint name="gps_joint" type="fixed">
      <parent>base_link</parent>	
      <child>gps_link</child>
      <pose>0 0 0 0 0 0</pose>
    </joint>

    <!-- *********************** WHEEL ODOMETRY *************************** -->
    <plugin name="bicycle_model_odometry" filename="libgazebo_ros_diff_drive.so">
      <update_rate>30</update_rate>
      <left_joint>rear_left_wheel_joint</left_joint>
      <right_joint>rear_right_wheel_joint</right_joint>
      <wheel_separation>0.52</wheel_separation>
      <wheel_diameter>0.28</wheel_diameter>
      <max_wheel_torque>20</max_wheel_torque>
      <max_wheel_acceleration>1.0</max_wheel_acceleration>
      <command_topic>cmd_vel</command_topic>
      <publish_odom>true</publish_odom>
      <publish_odom_tf>false</publish_odom_tf>
      <publish_wheel_tf>false</publish_wheel_tf>
      <odometry_topic>odom</odometry_topic>
      <odometry_frame>odom</odometry_frame>
      <robot_base_frame>base_footprint</robot_base_frame>
      <odometry_source>0</odometry_source>
      <ros>
        <remapping>odom:=wheel/odometry</remapping>
      </ros>
    </plugin>

    <!-- *********************** JOINT STATE PUBLISHER ********************* -->
    <plugin name="bicycle_model_joint_state" filename="libgazebo_ros_joint_state_publisher.so">
      <ros>
        <remapping>~/out:=joint_states</remapping>
      </ros>
      <update_rate>30</update_rate>
      <joint_name>rear_left_wheel_joint</joint_name>
      <joint_name>rear_right_wheel_joint</joint_name>
      <joint_name>steering_joint</joint_name>
      <joint_name>front_steering_wheel_joint</joint_name>
    </plugin>

  </model>
</sdf>

